<?xml version='1.0'?>
<robot name="moveo">

  <!-- Base Link -->
  <link name="base_link">
    <visual>
      <origin xyz="0 0 0.13" rpy="0 0 0"/>
      <geometry>
        <mesh filename="package://moveo_description/meshes/base_link.stl"/>
      </geometry>
      <material name="">
        <color rgba="0.75294 0.75294 0.75294 1"/>
      </material>
    </visual>
    <collision>
      <origin xyz="0 0 0.13" rpy="0 0 0"/>
      <geometry>
        <mesh filename="package://moveo_description/meshes/base_link_col.stl"/>
      </geometry>
    </collision>
  </link>

  <link name="Link_1">
    <inertial>
      <origin xyz="0.00004019 0.09063400 0.00010221" rpy="0 0 0"/>
      <mass value="4.2526"/>
      <inertia ixx="0.0034071" ixy="8.9041e-06" ixz="1.179e-07"
               iyy="0.018642" iyz="-3.6544e-06" izz="0.021987"/>
    </inertial>
    <visual>
      <origin xyz="0 0 0" rpy="0 0 0"/>
      <geometry>
        <mesh filename="package://moveo_description/meshes/Link_1.stl"/>
      </geometry>
      <material name="">
        <color rgba="0.75294 0.75294 0.75294 1"/>
      </material>
    </visual>
    <collision>
      <origin xyz="0 0 0" rpy="0 0 0"/>
      <geometry>
        <mesh filename="package://moveo_description/meshes/Link_1_col.stl"/>
      </geometry>
    </collision>
  </link>
  <joint name="Joint_1" type="revolute">
    <origin xyz="0.00000000 -0.24250000 0.13000000" rpy="1.57079633 0.00000367 1.20579347"/>
    <parent link="base_link"/>
    <child link="Link_1"/>
    <axis xyz="0 1 0"/>
    <limit lower="-1.5707" upper="1.5707" effort="5" velocity="1"/>
  </joint>

  <link name="Link_2">
    <inertial>
      <origin xyz="0.00002282 0.00176160 -0.08000200" rpy="0 0 0"/>
      <mass value="1.9323"/>
      <inertia ixx="0.012138" ixy="-3.5576e-06" ixz="-9.0632e-06"
               iyy="0.011445" iyz="0.00014273" izz="0.00070271"/>
    </inertial>
    <visual>
      <origin xyz="0 0 0" rpy="0 0 0"/>
      <geometry>
        <mesh filename="package://moveo_description/meshes/Link_2.stl"/>
      </geometry>
      <material name="">
        <color rgba="0.75294 0.75294 0.75294 1"/>
      </material>
    </visual>
    <collision>
      <origin xyz="0 0 0" rpy="0 0 0"/>
      <geometry>
        <mesh filename="package://moveo_description/meshes/Link_2_col.stl"/>
      </geometry>
    </collision>
  </link>
  <joint name="Joint_2" type="revolute">
    <origin xyz="0.00000000 0.18264000 0.00000000" rpy="1.57078667 1.57079206 0.00000000"/>
    <parent link="Link_1"/>
    <child link="Link_2"/>
    <axis xyz="0 -1 0"/>
    <limit lower="-1.5707" upper="1.5707" effort="5" velocity="1"/>
  </joint>

  <link name="Link_3">
    <inertial>
      <origin xyz="0.05095000 -0.00039084 -0.00045591" rpy="0 0 0"/>
      <mass value="1.1381"/>
      <inertia ixx="0.00023572" ixy="-3.8425e-06" ixz="4.1286e-06"
               iyy="0.00029123" iyz="-1.0387e-07" izz="0.00052457"/>
    </inertial>
    <visual>
      <origin xyz="0 0 0" rpy="0 0 0"/>
      <geometry>
        <mesh filename="package://moveo_description/meshes/Link_3.stl"/>
      </geometry>
      <material name="">
        <color rgba="0.75294 0.75294 0.75294 1"/>
      </material>
    </visual>
    <collision>
      <origin xyz="0 0 0" rpy="0 0 0"/>
      <geometry>
        <mesh filename="package://moveo_description/meshes/Link_3_col.stl"/>
      </geometry>
    </collision>
  </link>
  <joint name="Joint_3" type="revolute">
    <origin xyz="0.00000000 0.00000000 -0.22112000" rpy="0.00000124 1.56835920 0.00000000"/>
    <parent link="Link_2"/>
    <child link="Link_3"/>
    <axis xyz="0 -1 0"/>
    <limit lower="-1.5707" upper="1.5707" effort="5" velocity="1"/>
  </joint>

  <link name="Link_4">
    <inertial>
      <origin xyz="-0.00274170 0.00250970 0.01286400" rpy="0 0 0"/>
      <mass value="0.62964"/>
      <inertia ixx="0.0001717" ixy="1.3446e-06" ixz="8.5164e-06"
               iyy="0.00010506" iyz="5.1412e-05" izz="7.8944e-05"/>
    </inertial>
    <visual>
      <origin xyz="0 0 0" rpy="0 0 0"/>
      <geometry>
        <mesh filename="package://moveo_description/meshes/Link_4.stl"/>
      </geometry>
      <material name="">
        <color rgba="0.29412 0.29412 0.29412 1"/>
      </material>
    </visual>
    <collision>
      <origin xyz="0 0 0" rpy="0 0 0"/>
      <geometry>
        <mesh filename="package://moveo_description/meshes/Link_4_col.stl"/>
      </geometry>
    </collision>
  </link>
  <joint name="Joint_4" type="revolute">
    <origin xyz="0.16988000 -0.00099213 0.00000000" rpy="-0.04402676 1.00297628 -1.60635499"/>
    <parent link="Link_3"/>
    <child link="Link_4"/>
    <axis xyz="0.010353 -0.99993 -0.0059382"/>
    <limit lower="-1.5707" upper="1.5707" effort="5" velocity="1"/>
  </joint>

  <link name="Link_5">
    <inertial>
      <origin xyz="-0.01136600 0.00012239 0.00789670" rpy="0 0 0"/>
      <mass value="0.19875"/>
      <inertia ixx="6.2676e-05" ixy="4.2551e-06" ixz="4.0215e-05"
               iyy="9.7792e-05" iyz="8.5888e-07" izz="9.5807e-05"/>
    </inertial>
    <visual>
      <origin xyz="0 0 0" rpy="0 0 0"/>
      <geometry>
        <mesh filename="package://moveo_description/meshes/Link_5.stl"/>
      </geometry>
      <material name="">
        <color rgba="0.79216 0.81961 0.93333 1"/>
      </material>
    </visual>
    <collision>
      <origin xyz="0 0 0" rpy="0 0 0"/>
      <geometry>
        <mesh filename="package://moveo_description/meshes/Link_5_col.stl"/>
      </geometry>
    </collision>
  </link>
  <joint name="Joint_5" type="revolute">
    <origin xyz="-0.00213460 0.05304100 0.00169360" rpy="-1.48048705 0.01406373 -1.64986156"/>
    <parent link="Link_4"/>
    <child link="Link_5"/>
    <axis xyz="0 1 0"/>
    <limit lower="-1.5707" upper="1.5707" effort="5" velocity="1"/>
  </joint>

  <!-- ros2_control -->
  <ros2_control name="MoveoHardware" type="system">
    <hardware>
      <plugin>mock_components/GenericSystem</plugin>
    </hardware>
    <joint name="Joint_1">
      <command_interface name="position"/>
      <state_interface name="position"/>
      <state_interface name="velocity"/>
      <state_interface name="effort"/>
    </joint>
    <joint name="Joint_2">
      <command_interface name="position"/>
      <state_interface name="position"/>
      <state_interface name="velocity"/>
      <state_interface name="effort"/>
    </joint>
    <joint name="Joint_3">
      <command_interface name="position"/>
      <state_interface name="position"/>
      <state_interface name="velocity"/>
      <state_interface name="effort"/>
    </joint>
    <joint name="Joint_4">
      <command_interface name="position"/>
      <state_interface name="position"/>
      <state_interface name="velocity"/>
      <state_interface name="effort"/>
    </joint>
    <joint name="Joint_5">
      <command_interface name="position"/>
      <state_interface name="position"/>
      <state_interface name="velocity"/>
      <state_interface name="effort"/>
    </joint>
  </ros2_control>

</robot>
