<?xml version='1.0' encoding='utf-8'?>
<robot name="aero_hand_open_left">
  <link name="left_base_link">
    <inertial>
      <origin xyz="-0.00109122507694746 0.00334946623951281 0.0489855934276007" rpy="0 0 0" />
      <mass value="0.303576106034272" />
      <inertia ixx="0.0003204846476097" ixy="-2.62190795371995e-06" ixz="-1.78273132959694e-05" iyy="0.000498321260315036" iyz="-1.89908549049557e-05" izz="0.000236845827410211" />
    </inertial>
    <visual>
      <origin xyz="0 0 0" rpy="0 0 0" />
      <geometry>
        <mesh filename="package://aero_hand_open_description/meshes/left_base_link.STL" />
      </geometry>
      <material name="">
        <color rgba="0.7 0.7 0.7 1" />
      </material>
    </visual>
    <collision>
      <origin xyz="0 0 0" rpy="0 0 0" />
      <geometry>
        <mesh filename="package://aero_hand_open_description/meshes/left_base_link.STL" />
      </geometry>
    </collision>
  </link>
  <link name="left_t_link">
    <inertial>
      <origin xyz="0.000883525104759189 0.00170407980029484 0.00831028240403424" rpy="0 0 0" />
      <mass value="0.00833536405562315" />
      <inertia ixx="8.98196341850234e-07" ixy="-5.06324261689494e-08" ixz="-7.80847786775035e-08" iyy="6.56600038000196e-07" iyz="-1.15246746917096e-07" izz="4.94642305198558e-07" />
    </inertial>
    <visual>
      <origin xyz="0 0 0" rpy="0 0 0" />
      <geometry>
        <mesh filename="package://aero_hand_open_description/meshes/left_t_link.STL" />
      </geometry>
      <material name="">
        <color rgba="0.7 0.7 0.7 1" />
      </material>
    </visual>
    <collision>
      <origin xyz="0 0 0" rpy="0 0 0" />
      <geometry>
        <mesh filename="package://aero_hand_open_description/meshes/left_t_link.STL" />
      </geometry>
    </collision>
  </link>
  <joint name="left_thumb_cmc_abd" type="revolute">
    <origin xyz="-0.028112 -0.0145 0.025363" rpy="-1.2217 0 1.57" />
    <parent link="left_base_link" />
    <child link="left_t_link" />
    <axis xyz="0 -1 0" />
    <limit lower="0" upper="1.7453" effort="0" velocity="0" />
  </joint>
  <link name="left_thumb_mcp_link">
    <inertial>
      <origin xyz="1.9848e-07 0.00075445 0.014668" rpy="0 0 0" />
      <mass value="0.008207" />
      <inertia ixx="1.1501e-06" ixy="-1.5891e-11" ixz="2.1442e-11" iyy="1.2374e-06" iyz="2.9444e-08" izz="5.8804e-07" />
    </inertial>
    <visual>
      <origin xyz="0 0 0" rpy="0 0 0" />
      <geometry>
        <mesh filename="package://aero_hand_open_description/meshes/left_thumb_mcp_link.STL" />
      </geometry>
      <material name="">
        <color rgba="0.7 0.7 0.7 1" />
      </material>
    </visual>
    <collision>
      <origin xyz="0 0 0" rpy="0 0 0" />
      <geometry>
        <mesh filename="package://aero_hand_open_description/meshes/left_thumb_mcp_link.STL" />
      </geometry>
    </collision>
  </link>
  <joint name="left_thumb_cmc_flex" type="revolute">
    <origin xyz="0.003475 0.003808 0.019656" rpy="0.1325 0.17906 -0.26195" />
    <parent link="left_t_link" />
    <child link="left_thumb_mcp_link" />
    <axis xyz="1 0 0" />
    <limit lower="0" upper="0.9599" effort="0" velocity="0" />
  </joint>
  <link name="left_thumb_proximal_link">
    <inertial>
      <origin xyz="-7.9121e-09 0.001007 0.011955" rpy="0 0 0" />
      <mass value="0.005471" />
      <inertia ixx="5.6266e-07" ixy="1.2619e-11" ixz="-4.6488e-12" iyy="6.6259e-07" iyz="1.0326e-08" izz="3.2352e-07" />
    </inertial>
    <visual>
      <origin xyz="0 0 0" rpy="0 0 0" />
      <geometry>
        <mesh filename="package://aero_hand_open_description/meshes/left_thumb_proximal_link.STL" />
      </geometry>
      <material name="">
        <color rgba="0.7 0.7 0.7 1" />
      </material>
    </visual>
    <collision>
      <origin xyz="0 0 0" rpy="0 0 0" />
      <geometry>
        <mesh filename="package://aero_hand_open_description/meshes/left_thumb_proximal_link.STL" />
      </geometry>
    </collision>
  </link>
  <joint name="left_thumb_mcp" type="revolute">
    <origin xyz="0 0.0033822 0.035848" rpy="0 0 0" />
    <parent link="left_thumb_mcp_link" />
    <child link="left_thumb_proximal_link" />
    <axis xyz="1 0 0" />
    <limit lower="0" upper="1.5708" effort="0" velocity="0" />
  </joint>
  <link name="left_thumb_distal_link">
    <inertial>
      <origin xyz="6.4155e-07 -0.0011983 0.010377" rpy="0 0 0" />
      <mass value="0.0032396" />
      <inertia ixx="2.7433e-07" ixy="-3.5329e-12" ixz="-1.7025e-11" iyy="2.5791e-07" iyz="-5.5405e-08" izz="1.196e-07" />
    </inertial>
    <visual>
      <origin xyz="0 0 0" rpy="0 0 0" />
      <geometry>
        <mesh filename="package://aero_hand_open_description/meshes/left_thumb_distal_link.STL" />
      </geometry>
      <material name="">
        <color rgba="0.7 0.7 0.7 1" />
      </material>
    </visual>
    <collision>
      <origin xyz="0 0 0" rpy="0 0 0" />
      <geometry>
        <mesh filename="package://aero_hand_open_description/meshes/left_thumb_distal_link.STL" />
      </geometry>
    </collision>
  </link>
  <joint name="left_thumb_ip" type="revolute">
    <origin xyz="0 0.002206 0.029919" rpy="0 0 0" />
    <parent link="left_thumb_proximal_link" />
    <child link="left_thumb_distal_link" />
    <axis xyz="1 0 0" />
    <limit lower="0" upper="1.5708" effort="0" velocity="0" />
  </joint>
  <link name="left_thumb_tip_link">
    <inertial>
      <origin xyz="-2.2383e-07 -0.010203 -0.013939" rpy="0 0 0" />
      <mass value="0.00086967" />
      <inertia ixx="5.0257e-08" ixy="4.472e-12" ixz="3.8747e-12" iyy="6.2025e-08" iyz="-8.6371e-09" izz="3.845e-08" />
    </inertial>
    <visual>
      <origin xyz="0 0 0" rpy="0 0 0" />
      <geometry>
        <mesh filename="package://aero_hand_open_description/meshes/left_thumb_tip_link.STL" />
      </geometry>
      <material name="">
        <color rgba="0.7 0.7 0.7 1" />
      </material>
    </visual>
    <collision>
      <origin xyz="0 0 0" rpy="0 0 0" />
      <geometry>
        <mesh filename="package://aero_hand_open_description/meshes/left_thumb_tip_link.STL" />
      </geometry>
    </collision>
  </link>
  <joint name="left_thumb_tip" type="fixed">
    <origin xyz="0 0.0059474 0.031823" rpy="0 0 0" />
    <parent link="left_thumb_distal_link" />
    <child link="left_thumb_tip_link" />
    <axis xyz="0 0 0" />
  </joint>
  <link name="left_index_proximal_link">
    <inertial>
      <origin xyz="-4.30529992941076e-08 -0.0024559603959039 0.0191142514901699" rpy="0 0 0" />
      <mass value="0.00720026836301954" />
      <inertia ixx="1.11576979742814e-06" ixy="2.42664231429577e-12" ixz="8.53111702205322e-12" iyy="1.1011227010753e-06" iyz="1.07385658133945e-07" izz="2.80496727013047e-07" />
    </inertial>
    <visual>
      <origin xyz="0 0 0" rpy="0 0 0" />
      <geometry>
        <mesh filename="package://aero_hand_open_description/meshes/left_index_proximal_link.STL" />
      </geometry>
      <material name="">
        <color rgba="0.7 0.7 0.7 1" />
      </material>
    </visual>
    <collision>
      <origin xyz="0 0 0" rpy="0 0 0" />
      <geometry>
        <mesh filename="package://aero_hand_open_description/meshes/left_index_proximal_link.STL" />
      </geometry>
    </collision>
  </link>
  <joint name="left_index_mcp_flex" type="revolute">
    <origin xyz="-0.030626 -0.0011782 0.10542" rpy="0 -0.05236 0.034907" />
    <parent link="left_base_link" />
    <child link="left_index_proximal_link" />
    <axis xyz="1 0 0" />
    <limit lower="0" upper="1.5708" effort="0" velocity="0" />
  </joint>
  <link name="left_index_middle_link">
    <inertial>
      <origin xyz="6.47985752902369e-09 -0.000363269614703799 0.00876079008757696" rpy="0 0 0" />
      <mass value="0.00276150356687874" />
      <inertia ixx="1.80416885776444e-07" ixy="-1.11705685747945e-13" ixz="3.17914278530766e-14" iyy="1.9897239153381e-07" iyz="7.6558277494112e-09" izz="8.93351684671892e-08" />
    </inertial>
    <visual>
      <origin xyz="0 0 0" rpy="0 0 0" />
      <geometry>
        <mesh filename="package://aero_hand_open_description/meshes/left_index_middle_link.STL" />
      </geometry>
      <material name="">
        <color rgba="0.7 0.7 0.7 1" />
      </material>
    </visual>
    <collision>
      <origin xyz="0 0 0" rpy="0 0 0" />
      <geometry>
        <mesh filename="package://aero_hand_open_description/meshes/left_index_middle_link.STL" />
      </geometry>
    </collision>
  </link>
  <joint name="left_index_pip" type="revolute">
    <origin xyz="0 -0.0014554 0.043" rpy="0 0 0" />
    <parent link="left_index_proximal_link" />
    <child link="left_index_middle_link" />
    <axis xyz="1 0 0" />
    <limit lower="0" upper="1.5708" effort="0" velocity="0" />
  </joint>
  <link name="left_index_distal_link">
    <inertial>
      <origin xyz="-3.34671961321059e-07 -0.00120224143694181 0.00777234707760652" rpy="0 0 0" />
      <mass value="0.00183663667769987" />
      <inertia ixx="1.0824117936487e-07" ixy="-2.22622444751556e-12" ixz="-4.51561065548065e-13" iyy="1.0024267178837e-07" iyz="-1.85905628716286e-08" izz="3.57211667407306e-08" />
    </inertial>
    <visual>
      <origin xyz="0 0 0" rpy="0 0 0" />
      <geometry>
        <mesh filename="package://aero_hand_open_description/meshes/left_index_distal_link.STL" />
      </geometry>
      <material name="">
        <color rgba="0.7 0.7 0.7 1" />
      </material>
    </visual>
    <collision>
      <origin xyz="0 0 0" rpy="0 0 0" />
      <geometry>
        <mesh filename="package://aero_hand_open_description/meshes/left_index_distal_link.STL" />
      </geometry>
    </collision>
  </link>
  <joint name="left_index_dip" type="revolute">
    <origin xyz="0 0 0.022" rpy="0 0 0" />
    <parent link="left_index_middle_link" />
    <child link="left_index_distal_link" />
    <axis xyz="1 0 0" />
    <limit lower="0" upper="1.5708" effort="0" velocity="0" />
  </joint>
  <link name="left_index_tip_link">
    <inertial>
      <origin xyz="-2.3798090519056e-08 -0.00705353273135757 -0.0124434081224676" rpy="0 0 0" />
      <mass value="0.000390243409160287" />
      <inertia ixx="1.25259152366009e-08" ixy="-4.25868635620944e-13" ixz="9.33846395984465e-14" iyy="1.44813957341742e-08" iyz="-2.01061097814808e-09" izz="8.29652914701066e-09" />
    </inertial>
    <visual>
      <origin xyz="0 0 0" rpy="0 0 0" />
      <geometry>
        <mesh filename="package://aero_hand_open_description/meshes/left_index_tip_link.STL" />
      </geometry>
      <material name="">
        <color rgba="0.7 0.7 0.7 1" />
      </material>
    </visual>
    <collision>
      <origin xyz="0 0 0" rpy="0 0 0" />
      <geometry>
        <mesh filename="package://aero_hand_open_description/meshes/left_index_tip_link.STL" />
      </geometry>
    </collision>
  </link>
  <joint name="left_index_tip" type="fixed">
    <origin xyz="0 0.003512 0.026776" rpy="0 0 0" />
    <parent link="left_index_distal_link" />
    <child link="left_index_tip_link" />
    <axis xyz="0 0 0" />
  </joint>
  <link name="left_middle_proximal_link">
    <inertial>
      <origin xyz="-3.04863738940235e-08 -0.00245596411252013 0.0191142544123753" rpy="0 0 0" />
      <mass value="0.0072002618370038" />
      <inertia ixx="1.11576923655936e-06" ixy="2.87314711925059e-12" ixz="7.93183989281095e-12" iyy="1.10112189499846e-06" iyz="1.07384680629995e-07" izz="2.80496366633981e-07" />
    </inertial>
    <visual>
      <origin xyz="0 0 0" rpy="0 0 0" />
      <geometry>
        <mesh filename="package://aero_hand_open_description/meshes/left_middle_proximal_link.STL" />
      </geometry>
      <material name="">
        <color rgba="0.7 0.7 0.7 1" />
      </material>
    </visual>
    <collision>
      <origin xyz="0 0 0" rpy="0 0 0" />
      <geometry>
        <mesh filename="package://aero_hand_open_description/meshes/left_middle_proximal_link.STL" />
      </geometry>
    </collision>
  </link>
  <joint name="left_middle_mcp_flex" type="revolute">
    <origin xyz="-0.0075 0 0.106" rpy="0 0 0" />
    <parent link="left_base_link" />
    <child link="left_middle_proximal_link" />
    <axis xyz="1 0 0" />
    <limit lower="0" upper="1.5708" effort="0" velocity="0" />
  </joint>
  <link name="left_middle_middle_link">
    <inertial>
      <origin xyz="2.85973601964011e-09 -0.000363264332488778 0.00876078146450842" rpy="0 0 0" />
      <mass value="0.00276150069139886" />
      <inertia ixx="1.80416617173586e-07" ixy="-1.53011003427557e-13" ixz="1.41103664305574e-13" iyy="1.9897228701034e-07" iyz="7.6556903630071e-09" izz="8.9334989431654e-08" />
    </inertial>
    <visual>
      <origin xyz="0 0 0" rpy="0 0 0" />
      <geometry>
        <mesh filename="package://aero_hand_open_description/meshes/left_middle_middle_link.STL" />
      </geometry>
      <material name="">
        <color rgba="0.7 0.7 0.7 1" />
      </material>
    </visual>
    <collision>
      <origin xyz="0 0 0" rpy="0 0 0" />
      <geometry>
        <mesh filename="package://aero_hand_open_description/meshes/left_middle_middle_link.STL" />
      </geometry>
    </collision>
  </link>
  <joint name="left_middle_pip" type="revolute">
    <origin xyz="0 -0.0014554 0.043" rpy="0 0 0" />
    <parent link="left_middle_proximal_link" />
    <child link="left_middle_middle_link" />
    <axis xyz="1 0 0" />
    <limit lower="0" upper="1.5708" effort="0" velocity="0" />
  </joint>
  <link name="left_middle_distal_link">
    <inertial>
      <origin xyz="-1.25205983373364e-07 -0.00120223641223895 0.00777324919661349" rpy="0 0 0" />
      <mass value="0.00183690507488675" />
      <inertia ixx="1.08253108089546e-07" ixy="-2.19334961795908e-12" ixz="-2.52507113254221e-12" iyy="1.00254686909563e-07" iyz="-1.85902271227329e-08" izz="3.57231402201655e-08" />
    </inertial>
    <visual>
      <origin xyz="0 0 0" rpy="0 0 0" />
      <geometry>
        <mesh filename="package://aero_hand_open_description/meshes/left_middle_distal_link.STL" />
      </geometry>
      <material name="">
        <color rgba="0.7 0.7 0.7 1" />
      </material>
    </visual>
    <collision>
      <origin xyz="0 0 0" rpy="0 0 0" />
      <geometry>
        <mesh filename="package://aero_hand_open_description/meshes/left_middle_distal_link.STL" />
      </geometry>
    </collision>
  </link>
  <joint name="left_middle_dip" type="revolute">
    <origin xyz="0 0 0.022" rpy="0 0 0" />
    <parent link="left_middle_middle_link" />
    <child link="left_middle_distal_link" />
    <axis xyz="1 0 0" />
    <limit lower="0" upper="1.5708" effort="0" velocity="0" />
  </joint>
  <link name="left_middle_tip_link">
    <inertial>
      <origin xyz="7.96462318148356e-08 -0.00705328274533182 -0.0124432893968912" rpy="0 0 0" />
      <mass value="0.00039026895252879" />
      <inertia ixx="1.25266915345569e-08" ixy="-5.60524152388939e-13" ixz="1.88623261128416e-14" iyy="1.44817171092233e-08" iyz="-2.010901422928e-09" izz="8.29712543914407e-09" />
    </inertial>
    <visual>
      <origin xyz="0 0 0" rpy="0 0 0" />
      <geometry>
        <mesh filename="package://aero_hand_open_description/meshes/left_middle_tip_link.STL" />
      </geometry>
      <material name="">
        <color rgba="0.7 0.7 0.7 1" />
      </material>
    </visual>
    <collision>
      <origin xyz="0 0 0" rpy="0 0 0" />
      <geometry>
        <mesh filename="package://aero_hand_open_description/meshes/left_middle_tip_link.STL" />
      </geometry>
    </collision>
  </link>
  <joint name="left_middle_tip" type="fixed">
    <origin xyz="0 0.003512 0.026776" rpy="0 0 0" />
    <parent link="left_middle_distal_link" />
    <child link="left_middle_tip_link" />
    <axis xyz="0 0 0" />
  </joint>
  <link name="left_ring_proximal_link">
    <inertial>
      <origin xyz="2.24219388229863e-08 -0.00245596869794189 0.0191142172606163" rpy="0 0 0" />
      <mass value="0.00720026581090036" />
      <inertia ixx="1.11577050567807e-06" ixy="-5.89521141957177e-14" ixz="-1.83895388831523e-12" iyy="1.10112290329168e-06" iyz="1.07384543663671e-07" izz="2.8049685394292e-07" />
    </inertial>
    <visual>
      <origin xyz="0 0 0" rpy="0 0 0" />
      <geometry>
        <mesh filename="package://aero_hand_open_description/meshes/left_ring_proximal_link.STL" />
      </geometry>
      <material name="">
        <color rgba="0.7 0.7 0.7 1" />
      </material>
    </visual>
    <collision>
      <origin xyz="0 0 0" rpy="0 0 0" />
      <geometry>
        <mesh filename="package://aero_hand_open_description/meshes/left_ring_proximal_link.STL" />
      </geometry>
    </collision>
  </link>
  <joint name="left_ring_mcp_flex" type="revolute">
    <origin xyz="0.015626 -0.0011782 0.10542" rpy="0 0.05236 -0.034907" />
    <parent link="left_base_link" />
    <child link="left_ring_proximal_link" />
    <axis xyz="1 0 0" />
    <limit lower="0" upper="1.5708" effort="0" velocity="0" />
  </joint>
  <link name="left_ring_middle_link">
    <inertial>
      <origin xyz="1.05768104170789e-08 -0.000363267692106015 0.00876078358138278" rpy="0 0 0" />
      <mass value="0.00276150640462905" />
      <inertia ixx="1.80417110518944e-07" ixy="-2.51240159687594e-13" ixz="1.96663252625615e-13" iyy="1.98972658288888e-07" iyz="7.65587908401087e-09" izz="8.93352335930394e-08" />
    </inertial>
    <visual>
      <origin xyz="0 0 0" rpy="0 0 0" />
      <geometry>
        <mesh filename="package://aero_hand_open_description/meshes/left_ring_middle_link.STL" />
      </geometry>
      <material name="">
        <color rgba="0.7 0.7 0.7 1" />
      </material>
    </visual>
    <collision>
      <origin xyz="0 0 0" rpy="0 0 0" />
      <geometry>
        <mesh filename="package://aero_hand_open_description/meshes/left_ring_middle_link.STL" />
      </geometry>
    </collision>
  </link>
  <joint name="left_ring_pip" type="revolute">
    <origin xyz="0 -0.0014554 0.043" rpy="0 0 0" />
    <parent link="left_ring_proximal_link" />
    <child link="left_ring_middle_link" />
    <axis xyz="1 0 0" />
    <limit lower="0" upper="1.5708" effort="0" velocity="0" />
  </joint>
  <link name="left_ring_distal_link">
    <inertial>
      <origin xyz="-4.41236248528015e-07 -0.00120206116795719 0.0077717480697731" rpy="0 0 0" />
      <mass value="0.00183637337497735" />
      <inertia ixx="1.08230484308911e-07" ixy="-3.2022518221628e-12" ixz="-1.46160641586203e-14" iyy="1.00234337412801e-07" iyz="-1.85889383348734e-08" izz="3.57187511592097e-08" />
    </inertial>
    <visual>
      <origin xyz="0 0 0" rpy="0 0 0" />
      <geometry>
        <mesh filename="package://aero_hand_open_description/meshes/left_ring_distal_link.STL" />
      </geometry>
      <material name="">
        <color rgba="0.7 0.7 0.7 1" />
      </material>
    </visual>
    <collision>
      <origin xyz="0 0 0" rpy="0 0 0" />
      <geometry>
        <mesh filename="package://aero_hand_open_description/meshes/left_ring_distal_link.STL" />
      </geometry>
    </collision>
  </link>
  <joint name="left_ring_dip" type="revolute">
    <origin xyz="0 0 0.022" rpy="0 0 0" />
    <parent link="left_ring_middle_link" />
    <child link="left_ring_distal_link" />
    <axis xyz="1 0 0" />
    <limit lower="0" upper="1.5708" effort="0" velocity="0" />
  </joint>
  <link name="left_ring_tip_link">
    <inertial>
      <origin xyz="5.22173938463655e-09 -0.00705335731849239 -0.0124436468089668" rpy="0 0 0" />
      <mass value="0.000390294473374687" />
      <inertia ixx="1.2527015161699e-08" ixy="-6.38921187964615e-13" ixz="-1.87641904044513e-13" iyy="1.44821293282657e-08" iyz="-2.01081673399935e-09" izz="8.29710673013565e-09" />
    </inertial>
    <visual>
      <origin xyz="0 0 0" rpy="0 0 0" />
      <geometry>
        <mesh filename="package://aero_hand_open_description/meshes/left_ring_tip_link.STL" />
      </geometry>
      <material name="">
        <color rgba="0.7 0.7 0.7 1" />
      </material>
    </visual>
    <collision>
      <origin xyz="0 0 0" rpy="0 0 0" />
      <geometry>
        <mesh filename="package://aero_hand_open_description/meshes/left_ring_tip_link.STL" />
      </geometry>
    </collision>
  </link>
  <joint name="left_ring_tip" type="fixed">
    <origin xyz="0 0.003512 0.026776" rpy="0 0 0" />
    <parent link="left_ring_distal_link" />
    <child link="left_ring_tip_link" />
    <axis xyz="0 0 0" />
  </joint>
  <link name="left_pinky_proximal_link">
    <inertial>
      <origin xyz="2.95727574026183e-08 -0.00245597557732571 0.0191142201685638" rpy="0 0 0" />
      <mass value="0.00720026164932404" />
      <inertia ixx="1.11576993679738e-06" ixy="4.21493357126095e-14" ixz="-1.40217613791255e-12" iyy="1.10112215482059e-06" iyz="1.07383854570091e-07" izz="2.80496245620477e-07" />
    </inertial>
    <visual>
      <origin xyz="0 0 0" rpy="0 0 0" />
      <geometry>
        <mesh filename="package://aero_hand_open_description/meshes/left_pinky_proximal_link.STL" />
      </geometry>
      <material name="">
        <color rgba="0.7 0.7 0.7 1" />
      </material>
    </visual>
    <collision>
      <origin xyz="0 0 0" rpy="0 0 0" />
      <geometry>
        <mesh filename="package://aero_hand_open_description/meshes/left_pinky_proximal_link.STL" />
      </geometry>
    </collision>
  </link>
  <joint name="left_pinky_mcp_flex" type="revolute">
    <origin xyz="0.038266 -0.0036416 0.092393" rpy="0 0.10472 -0.069946" />
    <parent link="left_base_link" />
    <child link="left_pinky_proximal_link" />
    <axis xyz="1 0 0" />
    <limit lower="0" upper="1.5708" effort="0" velocity="0" />
  </joint>
  <link name="left_pinky_middle_link">
    <inertial>
      <origin xyz="7.30330518283751e-09 -0.000363268490759203 0.00876078540200605" rpy="0 0 0" />
      <mass value="0.00276150617991104" />
      <inertia ixx="1.80417146629369e-07" ixy="-2.77370887761691e-13" ixz="2.37462864018002e-13" iyy="1.98972592220503e-07" iyz="7.65598318320784e-09" izz="8.9335305249386e-08" />
    </inertial>
    <visual>
      <origin xyz="0 0 0" rpy="0 0 0" />
      <geometry>
        <mesh filename="package://aero_hand_open_description/meshes/left_pinky_middle_link.STL" />
      </geometry>
      <material name="">
        <color rgba="0.7 0.7 0.7 1" />
      </material>
    </visual>
    <collision>
      <origin xyz="0 0 0" rpy="0 0 0" />
      <geometry>
        <mesh filename="package://aero_hand_open_description/meshes/left_pinky_middle_link.STL" />
      </geometry>
    </collision>
  </link>
  <joint name="left_pinky_pip" type="revolute">
    <origin xyz="0 -0.0014554 0.043" rpy="0 0 0" />
    <parent link="left_pinky_proximal_link" />
    <child link="left_pinky_middle_link" />
    <axis xyz="1 0 0" />
    <limit lower="0" upper="1.5708" effort="0" velocity="0" />
  </joint>
  <link name="left_pinky_distal_link">
    <inertial>
      <origin xyz="-4.31454935043152e-07 -0.00120202346438717 0.00777263499391853" rpy="0 0 0" />
      <mass value="0.00183662951045839" />
      <inertia ixx="1.08241793280288e-07" ixy="-3.02667643229166e-12" ixz="1.26562320795476e-13" iyy="1.00245694664433e-07" iyz="-1.85886254587434e-08" izz="3.57206185143609e-08" />
    </inertial>
    <visual>
      <origin xyz="0 0 0" rpy="0 0 0" />
      <geometry>
        <mesh filename="package://aero_hand_open_description/meshes/left_pinky_distal_link.STL" />
      </geometry>
      <material name="">
        <color rgba="0.7 0.7 0.7 1" />
      </material>
    </visual>
    <collision>
      <origin xyz="0 0 0" rpy="0 0 0" />
      <geometry>
        <mesh filename="package://aero_hand_open_description/meshes/left_pinky_distal_link.STL" />
      </geometry>
    </collision>
  </link>
  <joint name="left_pinky_dip" type="revolute">
    <origin xyz="0 0 0.022" rpy="0 0 0" />
    <parent link="left_pinky_middle_link" />
    <child link="left_pinky_distal_link" />
    <axis xyz="1 0 0" />
    <limit lower="0" upper="1.5708" effort="0" velocity="0" />
  </joint>
  <link name="left_pinky_tip_link">
    <inertial>
      <origin xyz="-2.46097005066059e-08 -0.00705336045711742 -0.0124436503190868" rpy="0 0 0" />
      <mass value="0.000390294871676775" />
      <inertia ixx="1.25269642086474e-08" ixy="-6.55526982406491e-13" ixz="-1.63004750347713e-13" iyy="1.44821656097282e-08" iyz="-2.01083751842275e-09" izz="8.2971291296249e-09" />
    </inertial>
    <visual>
      <origin xyz="0 0 0" rpy="0 0 0" />
      <geometry>
        <mesh filename="package://aero_hand_open_description/meshes/left_pinky_tip_link.STL" />
      </geometry>
      <material name="">
        <color rgba="0.7 0.7 0.7 1" />
      </material>
    </visual>
    <collision>
      <origin xyz="0 0 0" rpy="0 0 0" />
      <geometry>
        <mesh filename="package://aero_hand_open_description/meshes/left_pinky_tip_link.STL" />
      </geometry>
    </collision>
  </link>
  <joint name="left_pinky_tip" type="fixed">
    <origin xyz="0 0.003512 0.026776" rpy="0 0 0" />
    <parent link="left_pinky_distal_link" />
    <child link="left_pinky_tip_link" />
    <axis xyz="0 0 0" />
  </joint>
</robot>