<?xml version="1.0" encoding="utf-8"?>
<!-- This URDF was automatically created by SolidWorks to URDF Exporter! Originally created by Stephen Brawner (brawner@gmail.com) 
     Commit Version: 1.6.0-4-g7f85cfe  Build Version: 1.6.7995.38578
     For more information, please see http://wiki.ros.org/sw_urdf_exporter -->
<robot name="aero_hand_open_right">
  <link name="right_base_link">
    <inertial>
      <origin xyz="0.00109122507694746 0.00334946623951281 0.0489855934276007" rpy="0 0 0" />
      <mass value="0.303576106034272" />
      <inertia ixx="0.0003204846476097" ixy="2.62190795371995E-06" ixz="1.78273132959694E-05" iyy="0.000498321260315036" iyz="-1.89908549049557E-05" izz="0.000236845827410211" />
    </inertial>
    <visual>
      <origin xyz="0 0 0" rpy="0 0 0" />
      <geometry>
        <mesh filename="package://aero_hand_open_description/meshes/right_base_link.STL" />
      </geometry>
      <material name="">
        <color rgba="0.7 0.7 0.7 1" />
      </material>
    </visual>
    <collision>
      <origin xyz="0 0 0" rpy="0 0 0" />
      <geometry>
        <mesh filename="package://aero_hand_open_description/meshes/right_base_link.STL" />
      </geometry>
    </collision>
  </link>
  <link name="right_t_link">
    <inertial>
      <origin xyz="-0.000883525104759189 0.00170407980029484 0.00831028240403424" rpy="0 0 0" />
      <mass value="0.00833536405562315" />
      <inertia ixx="8.98196341850234E-07" ixy="5.06324261689494E-08" ixz="7.80847786775035E-08" iyy="6.56600038000196E-07" iyz="-1.15246746917096E-07" izz="4.94642305198558E-07" />
    </inertial>
    <visual>
      <origin xyz="0 0 0" rpy="0 0 0" />
      <geometry>
        <mesh filename="package://aero_hand_open_description/meshes/right_t_link.STL" />
      </geometry>
      <material name="">
        <color rgba="0.7 0.7 0.7 1" />
      </material>
    </visual>
    <collision>
      <origin xyz="0 0 0" rpy="0 0 0" />
      <geometry>
        <mesh filename="package://aero_hand_open_description/meshes/right_t_link.STL" />
      </geometry>
    </collision>
  </link>
  <joint name="right_thumb_cmc_abd" type="revolute">
    <origin xyz="0.028112 -0.0145 0.025363" rpy="-1.2217 -0.0 -1.57" />
    <parent link="right_base_link" />
    <child link="right_t_link" />
    <axis xyz="0 1 0" />
    <limit lower="0" upper="1.7453" effort="0" velocity="0" />
  </joint>
  <link name="right_thumb_mcp_link">
    <inertial>
      <origin xyz="-1.9848E-07 0.00075445 0.014668" rpy="0 0 0" />
      <mass value="0.008207" />
      <inertia ixx="1.1501E-06" ixy="1.5891E-11" ixz="-2.1442E-11" iyy="1.2374E-06" iyz="2.9444E-08" izz="5.8804E-07" />
    </inertial>
    <visual>
      <origin xyz="0 0 0" rpy="0 0 0" />
      <geometry>
        <mesh filename="package://aero_hand_open_description/meshes/right_thumb_mcp_link.STL" />
      </geometry>
      <material name="">
        <color rgba="0.7 0.7 0.7 1" />
      </material>
    </visual>
    <collision>
      <origin xyz="0 0 0" rpy="0 0 0" />
      <geometry>
        <mesh filename="package://aero_hand_open_description/meshes/right_thumb_mcp_link.STL" />
      </geometry>
    </collision>
  </link>
  <joint name="right_thumb_cmc_flex" type="revolute">
    <origin xyz="-0.003475 0.003808 0.019656" rpy="0.1325 -0.17906 0.26195" />
    <parent link="right_t_link" />
    <child link="right_thumb_mcp_link" />
    <axis xyz="1 0 0" />
    <limit lower="0" upper="0.9599" effort="0" velocity="0" />
  </joint>
  <link name="right_thumb_proximal_link">
    <inertial>
      <origin xyz="7.9121E-09 0.001007 0.011955" rpy="0 0 0" />
      <mass value="0.005471" />
      <inertia ixx="5.6266E-07" ixy="-1.2619E-11" ixz="4.6488E-12" iyy="6.6259E-07" iyz="1.0326E-08" izz="3.2352E-07" />
    </inertial>
    <visual>
      <origin xyz="0 0 0" rpy="0 0 0" />
      <geometry>
        <mesh filename="package://aero_hand_open_description/meshes/right_thumb_proximal_link.STL" />
      </geometry>
      <material name="">
        <color rgba="0.7 0.7 0.7 1" />
      </material>
    </visual>
    <collision>
      <origin xyz="0 0 0" rpy="0 0 0" />
      <geometry>
        <mesh filename="package://aero_hand_open_description/meshes/right_thumb_proximal_link.STL" />
      </geometry>
    </collision>
  </link>
  <joint name="right_thumb_mcp" type="revolute">
    <origin xyz="0 0.0033822 0.035848" rpy="0 0 0" />
    <parent link="right_thumb_mcp_link" />
    <child link="right_thumb_proximal_link" />
    <axis xyz="1 0 0" />
    <limit lower="0" upper="1.5708" effort="0" velocity="0" />
  </joint>
  <link name="right_thumb_distal_link">
    <inertial>
      <origin xyz="-6.4155E-07 -0.0011983 0.010377" rpy="0 0 0" />
      <mass value="0.0032396" />
      <inertia ixx="2.7433E-07" ixy="3.5329E-12" ixz="1.7025E-11" iyy="2.5791E-07" iyz="-5.5405E-08" izz="1.196E-07" />
    </inertial>
    <visual>
      <origin xyz="0 0 0" rpy="0 0 0" />
      <geometry>
        <mesh filename="package://aero_hand_open_description/meshes/right_thumb_distal_link.STL" />
      </geometry>
      <material name="">
        <color rgba="0.7 0.7 0.7 1" />
      </material>
    </visual>
    <collision>
      <origin xyz="0 0 0" rpy="0 0 0" />
      <geometry>
        <mesh filename="package://aero_hand_open_description/meshes/right_thumb_distal_link.STL" />
      </geometry>
    </collision>
  </link>
  <joint name="right_thumb_ip" type="revolute">
    <origin xyz="0 0.002206 0.029919" rpy="0 0 0" />
    <parent link="right_thumb_proximal_link" />
    <child link="right_thumb_distal_link" />
    <axis xyz="1 0 0" />
    <limit lower="0" upper="1.5708" effort="0" velocity="0" />
  </joint>
  <link name="right_thumb_tip_link">
    <inertial>
      <origin xyz="2.2383E-07 -0.010203 -0.013939" rpy="0 0 0" />
      <mass value="0.00086967" />
      <inertia ixx="5.0257E-08" ixy="-4.472E-12" ixz="-3.8747E-12" iyy="6.2025E-08" iyz="-8.6371E-09" izz="3.845E-08" />
    </inertial>
    <visual>
      <origin xyz="0 0 0" rpy="0 0 0" />
      <geometry>
        <mesh filename="package://aero_hand_open_description/meshes/right_thumb_tip_link.STL" />
      </geometry>
      <material name="">
        <color rgba="0.7 0.7 0.7 1" />
      </material>
    </visual>
    <collision>
      <origin xyz="0 0 0" rpy="0 0 0" />
      <geometry>
        <mesh filename="package://aero_hand_open_description/meshes/right_thumb_tip_link.STL" />
      </geometry>
    </collision>
  </link>
  <joint name="right_thumb_tip" type="fixed">
    <origin xyz="0 0.0059474 0.031823" rpy="0 0 0" />
    <parent link="right_thumb_distal_link" />
    <child link="right_thumb_tip_link" />
    <axis xyz="0 0 0" />
  </joint>
  <link name="right_index_proximal_link">
    <inertial>
      <origin xyz="4.30529992941076E-08 -0.0024559603959039 0.0191142514901699" rpy="0 0 0" />
      <mass value="0.00720026836301954" />
      <inertia ixx="1.11576979742814E-06" ixy="-2.42664231429577E-12" ixz="-8.53111702205322E-12" iyy="1.1011227010753E-06" iyz="1.07385658133945E-07" izz="2.80496727013047E-07" />
    </inertial>
    <visual>
      <origin xyz="0 0 0" rpy="0 0 0" />
      <geometry>
        <mesh filename="package://aero_hand_open_description/meshes/right_index_proximal_link.STL" />
      </geometry>
      <material name="">
        <color rgba="0.7 0.7 0.7 1" />
      </material>
    </visual>
    <collision>
      <origin xyz="0 0 0" rpy="0 0 0" />
      <geometry>
        <mesh filename="package://aero_hand_open_description/meshes/right_index_proximal_link.STL" />
      </geometry>
    </collision>
  </link>
  <joint name="right_index_mcp_flex" type="revolute">
    <origin xyz="0.030626 -0.0011782 0.10542" rpy="0 0.05236 -0.034907" />
    <parent link="right_base_link" />
    <child link="right_index_proximal_link" />
    <axis xyz="1 0 0" />
    <limit lower="0" upper="1.5708" effort="0" velocity="0" />
  </joint>
  <link name="right_index_middle_link">
    <inertial>
      <origin xyz="-6.47985752902369E-09 -0.000363269614703799 0.00876079008757696" rpy="0 0 0" />
      <mass value="0.00276150356687874" />
      <inertia ixx="1.80416885776444E-07" ixy="1.11705685747945E-13" ixz="-3.17914278530766E-14" iyy="1.9897239153381E-07" iyz="7.6558277494112E-09" izz="8.93351684671892E-08" />
    </inertial>
    <visual>
      <origin xyz="0 0 0" rpy="0 0 0" />
      <geometry>
        <mesh filename="package://aero_hand_open_description/meshes/right_index_middle_link.STL" />
      </geometry>
      <material name="">
        <color rgba="0.7 0.7 0.7 1" />
      </material>
    </visual>
    <collision>
      <origin xyz="0 0 0" rpy="0 0 0" />
      <geometry>
        <mesh filename="package://aero_hand_open_description/meshes/right_index_middle_link.STL" />
      </geometry>
    </collision>
  </link>
  <joint name="right_index_pip" type="revolute">
    <origin xyz="0 -0.0014554 0.043" rpy="0 0 0" />
    <parent link="right_index_proximal_link" />
    <child link="right_index_middle_link" />
    <axis xyz="1 0 0" />
    <limit lower="0" upper="1.5708" effort="0" velocity="0" />
  </joint>
  <link name="right_index_distal_link">
    <inertial>
      <origin xyz="3.34671961321059E-07 -0.00120224143694181 0.00777234707760652" rpy="0 0 0" />
      <mass value="0.00183663667769987" />
      <inertia ixx="1.0824117936487E-07" ixy="2.22622444751556E-12" ixz="4.51561065548065E-13" iyy="1.0024267178837E-07" iyz="-1.85905628716286E-08" izz="3.57211667407306E-08" />
    </inertial>
    <visual>
      <origin xyz="0 0 0" rpy="0 0 0" />
      <geometry>
        <mesh filename="package://aero_hand_open_description/meshes/right_index_distal_link.STL" />
      </geometry>
      <material name="">
        <color rgba="0.7 0.7 0.7 1" />
      </material>
    </visual>
    <collision>
      <origin xyz="0 0 0" rpy="0 0 0" />
      <geometry>
        <mesh filename="package://aero_hand_open_description/meshes/right_index_distal_link.STL" />
      </geometry>
    </collision>
  </link>
  <joint name="right_index_dip" type="revolute">
    <origin xyz="0 0 0.022" rpy="0 0 0" />
    <parent link="right_index_middle_link" />
    <child link="right_index_distal_link" />
    <axis xyz="1 0 0" />
    <limit lower="0" upper="1.5708" effort="0" velocity="0" />
  </joint>
  <link name="right_index_tip_link">
    <inertial>
      <origin xyz="2.3798090519056E-08 -0.00705353273135757 -0.0124434081224676" rpy="0 0 0" />
      <mass value="0.000390243409160287" />
      <inertia ixx="1.25259152366009E-08" ixy="4.25868635620944E-13" ixz="-9.33846395984465E-14" iyy="1.44813957341742E-08" iyz="-2.01061097814808E-09" izz="8.29652914701066E-09" />
    </inertial>
    <visual>
      <origin xyz="0 0 0" rpy="0 0 0" />
      <geometry>
        <mesh filename="package://aero_hand_open_description/meshes/right_index_tip_link.STL" />
      </geometry>
      <material name="">
        <color rgba="0.7 0.7 0.7 1" />
      </material>
    </visual>
    <collision>
      <origin xyz="0 0 0" rpy="0 0 0" />
      <geometry>
        <mesh filename="package://aero_hand_open_description/meshes/right_index_tip_link.STL" />
      </geometry>
    </collision>
  </link>
  <joint name="right_index_tip" type="fixed">
    <origin xyz="0 0.003512 0.026776" rpy="0 0 0" />
    <parent link="right_index_distal_link" />
    <child link="right_index_tip_link" />
    <axis xyz="0 0 0" />
  </joint>
  <link name="right_middle_proximal_link">
    <inertial>
      <origin xyz="3.04863738940235E-08 -0.00245596411252013 0.0191142544123753" rpy="0 0 0" />
      <mass value="0.0072002618370038" />
      <inertia ixx="1.11576923655936E-06" ixy="-2.87314711925059E-12" ixz="-7.93183989281095E-12" iyy="1.10112189499846E-06" iyz="1.07384680629995E-07" izz="2.80496366633981E-07" />
    </inertial>
    <visual>
      <origin xyz="0 0 0" rpy="0 0 0" />
      <geometry>
        <mesh filename="package://aero_hand_open_description/meshes/right_middle_proximal_link.STL" />
      </geometry>
      <material name="">
        <color rgba="0.7 0.7 0.7 1" />
      </material>
    </visual>
    <collision>
      <origin xyz="0 0 0" rpy="0 0 0" />
      <geometry>
        <mesh filename="package://aero_hand_open_description/meshes/right_middle_proximal_link.STL" />
      </geometry>
    </collision>
  </link>
  <joint name="right_middle_mcp_flex" type="revolute">
    <origin xyz="0.0075 0 0.106" rpy="0 0 0" />
    <parent link="right_base_link" />
    <child link="right_middle_proximal_link" />
    <axis xyz="1 0 0" />
    <limit lower="0" upper="1.5708" effort="0" velocity="0" />
  </joint>
  <link name="right_middle_middle_link">
    <inertial>
      <origin xyz="-2.85973601964011E-09 -0.000363264332488778 0.00876078146450842" rpy="0 0 0" />
      <mass value="0.00276150069139886" />
      <inertia ixx="1.80416617173586E-07" ixy="1.53011003427557E-13" ixz="-1.41103664305574E-13" iyy="1.9897228701034E-07" iyz="7.6556903630071E-09" izz="8.9334989431654E-08" />
    </inertial>
    <visual>
      <origin xyz="0 0 0" rpy="0 0 0" />
      <geometry>
        <mesh filename="package://aero_hand_open_description/meshes/right_middle_middle_link.STL" />
      </geometry>
      <material name="">
        <color rgba="0.7 0.7 0.7 1" />
      </material>
    </visual>
    <collision>
      <origin xyz="0 0 0" rpy="0 0 0" />
      <geometry>
        <mesh filename="package://aero_hand_open_description/meshes/right_middle_middle_link.STL" />
      </geometry>
    </collision>
  </link>
  <joint name="right_middle_pip" type="revolute">
    <origin xyz="0 -0.0014554 0.043" rpy="0 0 0" />
    <parent link="right_middle_proximal_link" />
    <child link="right_middle_middle_link" />
    <axis xyz="1 0 0" />
    <limit lower="0" upper="1.5708" effort="0" velocity="0" />
  </joint>
  <link name="right_middle_distal_link">
    <inertial>
      <origin xyz="1.25205983373364E-07 -0.00120223641223895 0.00777324919661349" rpy="0 0 0" />
      <mass value="0.00183690507488675" />
      <inertia ixx="1.08253108089546E-07" ixy="2.19334961795908E-12" ixz="2.52507113254221E-12" iyy="1.00254686909563E-07" iyz="-1.85902271227329E-08" izz="3.57231402201655E-08" />
    </inertial>
    <visual>
      <origin xyz="0 0 0" rpy="0 0 0" />
      <geometry>
        <mesh filename="package://aero_hand_open_description/meshes/right_middle_distal_link.STL" />
      </geometry>
      <material name="">
        <color rgba="0.7 0.7 0.7 1" />
      </material>
    </visual>
    <collision>
      <origin xyz="0 0 0" rpy="0 0 0" />
      <geometry>
        <mesh filename="package://aero_hand_open_description/meshes/right_middle_distal_link.STL" />
      </geometry>
    </collision>
  </link>
  <joint name="right_middle_dip" type="revolute">
    <origin xyz="0 0 0.022" rpy="0 0 0" />
    <parent link="right_middle_middle_link" />
    <child link="right_middle_distal_link" />
    <axis xyz="1 0 0" />
    <limit lower="0" upper="1.5708" effort="0" velocity="0" />
  </joint>
  <link name="right_middle_tip_link">
    <inertial>
      <origin xyz="-7.96462318148356E-08 -0.00705328274533182 -0.0124432893968912" rpy="0 0 0" />
      <mass value="0.00039026895252879" />
      <inertia ixx="1.25266915345569E-08" ixy="5.60524152388939E-13" ixz="-1.88623261128416E-14" iyy="1.44817171092233E-08" iyz="-2.010901422928E-09" izz="8.29712543914407E-09" />
    </inertial>
    <visual>
      <origin xyz="0 0 0" rpy="0 0 0" />
      <geometry>
        <mesh filename="package://aero_hand_open_description/meshes/right_middle_tip_link.STL" />
      </geometry>
      <material name="">
        <color rgba="0.7 0.7 0.7 1" />
      </material>
    </visual>
    <collision>
      <origin xyz="0 0 0" rpy="0 0 0" />
      <geometry>
        <mesh filename="package://aero_hand_open_description/meshes/right_middle_tip_link.STL" />
      </geometry>
    </collision>
  </link>
  <joint name="right_middle_tip" type="fixed">
    <origin xyz="0 0.003512 0.026776" rpy="0 0 0" />
    <parent link="right_middle_distal_link" />
    <child link="right_middle_tip_link" />
    <axis xyz="0 0 0" />
  </joint>
  <link name="right_ring_proximal_link">
    <inertial>
      <origin xyz="-2.24219388229863E-08 -0.00245596869794189 0.0191142172606163" rpy="0 0 0" />
      <mass value="0.00720026581090036" />
      <inertia ixx="1.11577050567807E-06" ixy="5.89521141957177E-14" ixz="1.83895388831523E-12" iyy="1.10112290329168E-06" iyz="1.07384543663671E-07" izz="2.8049685394292E-07" />
    </inertial>
    <visual>
      <origin xyz="0 0 0" rpy="0 0 0" />
      <geometry>
        <mesh filename="package://aero_hand_open_description/meshes/right_ring_proximal_link.STL" />
      </geometry>
      <material name="">
        <color rgba="0.7 0.7 0.7 1" />
      </material>
    </visual>
    <collision>
      <origin xyz="0 0 0" rpy="0 0 0" />
      <geometry>
        <mesh filename="package://aero_hand_open_description/meshes/right_ring_proximal_link.STL" />
      </geometry>
    </collision>
  </link>
  <joint name="right_ring_mcp_flex" type="revolute">
    <origin xyz="-0.015626 -0.0011782 0.10542" rpy="0 -0.05236 0.034907" />
    <parent link="right_base_link" />
    <child link="right_ring_proximal_link" />
    <axis xyz="1 0 0" />
    <limit lower="0" upper="1.5708" effort="0" velocity="0" />
  </joint>
  <link name="right_ring_middle_link">
    <inertial>
      <origin xyz="-1.05768104170789E-08 -0.000363267692106015 0.00876078358138278" rpy="0 0 0" />
      <mass value="0.00276150640462905" />
      <inertia ixx="1.80417110518944E-07" ixy="2.51240159687594E-13" ixz="-1.96663252625615E-13" iyy="1.98972658288888E-07" iyz="7.65587908401087E-09" izz="8.93352335930394E-08" />
    </inertial>
    <visual>
      <origin xyz="0 0 0" rpy="0 0 0" />
      <geometry>
        <mesh filename="package://aero_hand_open_description/meshes/right_ring_middle_link.STL" />
      </geometry>
      <material name="">
        <color rgba="0.7 0.7 0.7 1" />
      </material>
    </visual>
    <collision>
      <origin xyz="0 0 0" rpy="0 0 0" />
      <geometry>
        <mesh filename="package://aero_hand_open_description/meshes/right_ring_middle_link.STL" />
      </geometry>
    </collision>
  </link>
  <joint name="right_ring_pip" type="revolute">
    <origin xyz="0 -0.0014554 0.043" rpy="0 0 0" />
    <parent link="right_ring_proximal_link" />
    <child link="right_ring_middle_link" />
    <axis xyz="1 0 0" />
    <limit lower="0" upper="1.5708" effort="0" velocity="0" />
  </joint>
  <link name="right_ring_distal_link">
    <inertial>
      <origin xyz="4.41236248528015E-07 -0.00120206116795719 0.0077717480697731" rpy="0 0 0" />
      <mass value="0.00183637337497735" />
      <inertia ixx="1.08230484308911E-07" ixy="3.2022518221628E-12" ixz="1.46160641586203E-14" iyy="1.00234337412801E-07" iyz="-1.85889383348734E-08" izz="3.57187511592097E-08" />
    </inertial>
    <visual>
      <origin xyz="0 0 0" rpy="0 0 0" />
      <geometry>
        <mesh filename="package://aero_hand_open_description/meshes/right_ring_distal_link.STL" />
      </geometry>
      <material name="">
        <color rgba="0.7 0.7 0.7 1" />
      </material>
    </visual>
    <collision>
      <origin xyz="0 0 0" rpy="0 0 0" />
      <geometry>
        <mesh filename="package://aero_hand_open_description/meshes/right_ring_distal_link.STL" />
      </geometry>
    </collision>
  </link>
  <joint name="right_ring_dip" type="revolute">
    <origin xyz="0 0 0.022" rpy="0 0 0" />
    <parent link="right_ring_middle_link" />
    <child link="right_ring_distal_link" />
    <axis xyz="1 0 0" />
    <limit lower="0" upper="1.5708" effort="0" velocity="0" />
  </joint>
  <link name="right_ring_tip_link">
    <inertial>
      <origin xyz="-5.22173938463655E-09 -0.00705335731849239 -0.0124436468089668" rpy="0 0 0" />
      <mass value="0.000390294473374687" />
      <inertia ixx="1.2527015161699E-08" ixy="6.38921187964615E-13" ixz="1.87641904044513E-13" iyy="1.44821293282657E-08" iyz="-2.01081673399935E-09" izz="8.29710673013565E-09" />
    </inertial>
    <visual>
      <origin xyz="0 0 0" rpy="0 0 0" />
      <geometry>
        <mesh filename="package://aero_hand_open_description/meshes/right_ring_tip_link.STL" />
      </geometry>
      <material name="">
        <color rgba="0.7 0.7 0.7 1" />
      </material>
    </visual>
    <collision>
      <origin xyz="0 0 0" rpy="0 0 0" />
      <geometry>
        <mesh filename="package://aero_hand_open_description/meshes/right_ring_tip_link.STL" />
      </geometry>
    </collision>
  </link>
  <joint name="right_ring_tip" type="fixed">
    <origin xyz="0 0.003512 0.026776" rpy="0 0 0" />
    <parent link="right_ring_distal_link" />
    <child link="right_ring_tip_link" />
    <axis xyz="0 0 0" />
  </joint>
  <link name="right_pinky_proximal_link">
    <inertial>
      <origin xyz="-2.95727574026183E-08 -0.00245597557732571 0.0191142201685638" rpy="0 0 0" />
      <mass value="0.00720026164932404" />
      <inertia ixx="1.11576993679738E-06" ixy="-4.21493357126095E-14" ixz="1.40217613791255E-12" iyy="1.10112215482059E-06" iyz="1.07383854570091E-07" izz="2.80496245620477E-07" />
    </inertial>
    <visual>
      <origin xyz="0 0 0" rpy="0 0 0" />
      <geometry>
        <mesh filename="package://aero_hand_open_description/meshes/right_pinky_proximal_link.STL" />
      </geometry>
      <material name="">
        <color rgba="0.7 0.7 0.7 1" />
      </material>
    </visual>
    <collision>
      <origin xyz="0 0 0" rpy="0 0 0" />
      <geometry>
        <mesh filename="package://aero_hand_open_description/meshes/right_pinky_proximal_link.STL" />
      </geometry>
    </collision>
  </link>
  <joint name="right_pinky_mcp_flex" type="revolute">
    <origin xyz="-0.038266 -0.0036416 0.092393" rpy="0 -0.10472 0.069946" />
    <parent link="right_base_link" />
    <child link="right_pinky_proximal_link" />
    <axis xyz="1 0 0" />
    <limit lower="0" upper="1.5708" effort="0" velocity="0" />
  </joint>
  <link name="right_pinky_middle_link">
    <inertial>
      <origin xyz="-7.30330518283751E-09 -0.000363268490759203 0.00876078540200605" rpy="0 0 0" />
      <mass value="0.00276150617991104" />
      <inertia ixx="1.80417146629369E-07" ixy="2.77370887761691E-13" ixz="-2.37462864018002E-13" iyy="1.98972592220503E-07" iyz="7.65598318320784E-09" izz="8.9335305249386E-08" />
    </inertial>
    <visual>
      <origin xyz="0 0 0" rpy="0 0 0" />
      <geometry>
        <mesh filename="package://aero_hand_open_description/meshes/right_pinky_middle_link.STL" />
      </geometry>
      <material name="">
        <color rgba="0.7 0.7 0.7 1" />
      </material>
    </visual>
    <collision>
      <origin xyz="0 0 0" rpy="0 0 0" />
      <geometry>
        <mesh filename="package://aero_hand_open_description/meshes/right_pinky_middle_link.STL" />
      </geometry>
    </collision>
  </link>
  <joint name="right_pinky_pip" type="revolute">
    <origin xyz="0 -0.0014554 0.043" rpy="0 0 0" />
    <parent link="right_pinky_proximal_link" />
    <child link="right_pinky_middle_link" />
    <axis xyz="1 0 0" />
    <limit lower="0" upper="1.5708" effort="0" velocity="0" />
  </joint>
  <link name="right_pinky_distal_link">
    <inertial>
      <origin xyz="4.31454935043152E-07 -0.00120202346438717 0.00777263499391853" rpy="0 0 0" />
      <mass value="0.00183662951045839" />
      <inertia ixx="1.08241793280288E-07" ixy="3.02667643229166E-12" ixz="-1.26562320795476E-13" iyy="1.00245694664433E-07" iyz="-1.85886254587434E-08" izz="3.57206185143609E-08" />
    </inertial>
    <visual>
      <origin xyz="0 0 0" rpy="0 0 0" />
      <geometry>
        <mesh filename="package://aero_hand_open_description/meshes/right_pinky_distal_link.STL" />
      </geometry>
      <material name="">
        <color rgba="0.7 0.7 0.7 1" />
      </material>
    </visual>
    <collision>
      <origin xyz="0 0 0" rpy="0 0 0" />
      <geometry>
        <mesh filename="package://aero_hand_open_description/meshes/right_pinky_distal_link.STL" />
      </geometry>
    </collision>
  </link>
  <joint name="right_pinky_dip" type="revolute">
    <origin xyz="0 0 0.022" rpy="0 0 0" />
    <parent link="right_pinky_middle_link" />
    <child link="right_pinky_distal_link" />
    <axis xyz="1 0 0" />
    <limit lower="0" upper="1.5708" effort="0" velocity="0" />
  </joint>
  <link name="right_pinky_tip_link">
    <inertial>
      <origin xyz="2.46097005066059E-08 -0.00705336045711742 -0.0124436503190868" rpy="0 0 0" />
      <mass value="0.000390294871676775" />
      <inertia ixx="1.25269642086474E-08" ixy="6.55526982406491E-13" ixz="1.63004750347713E-13" iyy="1.44821656097282E-08" iyz="-2.01083751842275E-09" izz="8.2971291296249E-09" />
    </inertial>
    <visual>
      <origin xyz="0 0 0" rpy="0 0 0" />
      <geometry>
        <mesh filename="package://aero_hand_open_description/meshes/right_pinky_tip_link.STL" />
      </geometry>
      <material name="">
        <color rgba="0.7 0.7 0.7 1" />
      </material>
    </visual>
    <collision>
      <origin xyz="0 0 0" rpy="0 0 0" />
      <geometry>
        <mesh filename="package://aero_hand_open_description/meshes/right_pinky_tip_link.STL" />
      </geometry>
    </collision>
  </link>
  <joint name="right_pinky_tip" type="fixed">
    <origin xyz="0 0.003512 0.026776" rpy="0 0 0" />
    <parent link="right_pinky_distal_link" />
    <child link="right_pinky_tip_link" />
    <axis xyz="0 0 0" />
  </joint>
</robot>